Workbook

Sheet Guide
A1: ACIDHOUSE FERMENTATION: CALCULATOR FOR KOJI
A2: Traditional calculations for sake, miso, amazake, shio koji, mirin, vinegar, and other koji-based ferments
A3: Version 413
A5: SUPPORT THE COMMUNITY
B6: The Sake Brewers Guild shares fermentation knowledge freely. If you find this calculator useful, please consider supporting their work. They offer free seminars, a Discord community, and translated resources for 5,000+ brewers worldwide. | C6: Please Donate
A9: QUICK START
A11: 1. Go to Recipe sheet → Enter total rice (kg) in B4
A12: 2. Select a Recipe preset from B5 dropdown (or customize)
A13: 3. Select rice variety and polish ratio for each lot
A14: 4. View calculated totals: rice, koji, water, mash volume
A15: 5. Use Plan sheet for detailed stage breakdowns
A16: 6. Use Quick Calc for standalone calculations
A17: 7. Use Koji Ferments for miso, amazake, mirin, shoyu, etc.
A18: 8. All blue cells are inputs; gray cells are calculated
A20: VISUAL KEY
A22: Light blue | B22: Select ▽ | C22: User input — dropdown or free entry
A23: Light green | B23: Sample | C23: User input — free entry, numeric
A24: Light gray | B24: Sample | C24: Calculated value — do not edit
A25: White | B25: Sample | C25: Label or static text
A26: Red triangle | B26: Hover here | C26: Hover over cell B26 to see example — Toji notes explain brewing logic
A27: Japanese terms | B27: 漢字 (かな) | C27: Kanji with hiragana/katakana reading to aid pronunciation and learning
A30: PHILOSOPHY
A32: Sake brewing developed significantly within Buddhist temples in Japan. By the 15th century, soboshu (僧坊酒)—monk sake—from institutions like Shoryakuji Temple in Nara had become renowned. The Tamon-in Nikki (多聞院日記), diaries kept by monks at Kofukuji Temple from 1478 to 1618, document brewing techniques still studied today. These monks developed bodaimoto, using naturally cultivated lactic acid bacteria to protect fermentation—centuries before the underlying microbiology was understood.
A34: Shinto tradition regards rice as sacred. Inari Ōkami (稲荷大神), one of the most widely venerated kami, presides over rice, fertility, and agriculture. Over 30,000 Inari shrines across Japan reflect this relationship with rice cultivation. Sake offered at shrines (omiki/御神酒) connects brewing to religious practice. Some breweries maintain these connections—Terada Honke draws water from a shrine forest spring.
A36: The concept of Hakkodo (発酵道)—the Way of Fermentation—frames brewing as a practice requiring attention and responsiveness. Keisuke Terada, 23rd-generation owner of Terada Honke, describes fermentation as requiring constant adjustment to changing conditions. This aligns with Buddhist teachings on impermanence (mujō/無常): the brewer observes and responds rather than imposing fixed expectations.
A38: Traditional toji develop skills through observation—recognizing the chestnut aroma of healthy koji, the texture change as hyphae develop, the temperature rise in an active moto. The saying 'ichi-koji, ni-moto, san-tsukuri' (first koji, second starter, third brewing) reflects the importance of foundational steps. These observational skills remain valuable even as scientific instruments provide additional data.
A40: Modern research from NRIB (酒類総合研究所), the Brewing Society of Japan, and academic journals documents the biochemistry behind traditional methods. Understanding enzyme kinetics, microbial ecology, and fermentation chemistry explains why certain practices work. Many brewers find that scientific knowledge and traditional observation complement each other.
A42: Brewing knowledge has been transmitted through apprenticeship, guild systems, and written records for centuries. The techniques documented here—kimoto, bodaimoto, sandan-jikomi, various koji cultivation methods—represent accumulated practical knowledge. This calculator aims to make some of that knowledge accessible in a structured format.
A44: Similar fermentation principles appear across cultures. The same Lactobacillus species that culture Japanese nukazuke also preserve Korean kimchi. Saccharomyces cerevisiae produces both sake and wine. Aspergillus molds are used throughout East Asian food production. Fermentation knowledge crosses boundaries.
A46: ABOUT ACIDHOUSE
A48: Acidhouse Fermentation is a food company. We aim to make sake, vinegar, mirin, miso, shio koji, and other koji-based foods—transforming simple ingredients into something profound. Our real work is knowledge sharing: demonstrating how koji-based fermentation can address food waste, improve plant protein digestibility, reduce sodium in processed foods, and enable decentralized, low-energy food production.
A50: WHY FERMENTATION MATTERS NOW
A52: THE MODERN HEALTH CRISIS
... A77: GUT HEALTH & FERMENTED FOODS
A78: Cell Metabolism (2024) | B78: cell.com/cell-metabolism/fulltext/S1550-4131(24)00086-X
A79: Microbial Biotechnology (2024) | B79: doi.org/10.1111/1751-7915.14428
A80: Nutrients (2022) | B80: mdpi.com/2072-6643/14/7/1527
A81: Nature Communications (2025) | B81: nature.com/articles/s41467-025-56014-6
A83: SCREEN TIME & GUT-BRAIN AXIS
A84: Scientific Reports (2022) | B84: nature.com/articles/s41598-022-07381-3
...

Sheet Recipe
A1: Sake Recipe Calculator | F1: v539
A3: RECIPE SETTINGS
A4: Total rice (kg) | B4: 99
A5: Recipe | B5: Select ▽
A6: Moto type | B6: =IFERROR(IF(Plan!B36="Select ▽","→ See Plan",Plan!B36),"") -> → See Plan
A7: Koji strain | B7: Select ▽
A8: Koji style | B8: Select ▽
A9: RICE LOTS
A10: Lot | B10: Variety | C10: Polish (%) | D10: Batch ID
A11: Lot A | B11: Select ▽
A12: Lot B | B12: Select ▽
A13: Lot C | B13: Select ▽
A14: Lot D | B14: Select ▽
A16: RICE ALLOCATIONS
A17: Addition | B17: Lot | C17: % | D17: Lot 2 | E17: % (auto)
A18: Kojimai | B18: Lot A | C18: 100 | D18: Select ▽ | E18: =IF(OR(D18="",D18="Select"),"",100-C18) -> 0
A19: Moto raw | B19: Lot A | C19: 100 | D19: Select ▽ | E19: =IF(OR(D19="",D19="Select"),"",100-C19) -> 0
A20: Moto steamed | B20: Lot A | C20: 100 | D20: Select ▽ | E20: =IF(OR(D20="",D20="Select"),"",100-C20) -> 0
A21: Soe | B21: Lot A | C21: 100 | D21: Select ▽ | E21: =IF(OR(D21="",D21="Select"),"",100-C21) -> 0
A22: Naka | B22: Lot A | C22: 100 | D22: Select ▽ | E22: =IF(OR(D22="",D22="Select"),"",100-C22) -> 0
A23: Tome | B23: Lot A | C23: 100 | D23: Select ▽ | E23: =IF(OR(D23="",D23="Select"),"",100-C23) -> 0
A24: Yondan | B24: Lot A | C24: 100 | D24: Select ▽ | E24: =IF(OR(D24="",D24="Select"),"",100-C24) -> 0
A26: CALCULATED TOTALS
A27: Total DRY rice (kg) | B27: =IF(OR(_Inputs!B4="",_Inputs!B4=0),"",_Inputs!B4) -> 99
A28: Moto raw rice (kg) | B28: =IFERROR(IF(OR(_Allocations!B23="",_Allocations!B23=0),"",_Allocations!B23),"")
A29: Rice to steam (kg) | B29: =IFERROR(IF(OR(B27="",B27=0),"",B27-IFERROR(IF(OR(B28="",B28="-"),0,B28),0)),"") -> 99
A30: Koji (kg dry) | B30: =IFERROR(IF(_Allocations!B3="","",_Allocations!B3),"") -> 21.78
A31: Total water (L) | B31: =IFERROR(IF(_Allocations!B4="","",_Allocations!B4),"") -> 128.7
A32: Total water (%) | B32: =IFERROR(IF(OR(B4="",B4=0,B31=""),"",ROUND(B31/B4*100,0)),"") -> 130
A33: RiceWater ratio | B33: =IFERROR(IF(OR(B4="",B31=""),"",ROUND(B31/B4,2)),"") -> 1.3
A34: Mash volume (L) | B34: =IFERROR(IF(_Allocations!B6="","",ROUND(_Allocations!B6,2)),"") -> 267.74
A35: Genshu yield (L) | B35: =IFERROR(IF(_Allocations!B7="","",ROUND(_Allocations!B7,2)),"") -> 121.18
A36: Press method | B36: Select ▽
A37: Yield @15% ABV (L) | B37: =IFERROR(IF(_Allocations!B8="","",ROUND(_Allocations!B8,2)),"") -> 147.03
A38: STAGE BREAKDOWN
A39: STAGE | B39: Raw (kg) | C39: Koji (kg) | D39: Kakemai (kg) | E39: Water (L) | F39: W:R ratio
A40: Moto | B40: =IFERROR(IF(OR(_Allocations!B23="",_Allocations!B23=0),"-",ROUND(_Allocations!B23,2)),"-") -> - | C40: =IFERROR(IF(OR(_Allocations!C11="",_Allocations!C11=0),"-",ROUND(_Allocations!C11,2)),"-") -> 2.29 | D40: =IFERROR(IF(OR(_Allocations!B24="",_Allocations!B24=0),"-",ROUND(_Allocations!B24,2)),"-") -> 4.64 | E40: =IFERROR(IF(_Allocations!D11="","-",ROUND(_Allocations!D11,2)),"-") -> 7.62 | F40: =IFERROR(IF(_Allocations!D11="","-",ROUND(_Allocations!D11/(_Allocations!C11+_Allocations!B24+_Allocations!B23),2)),"-") -> 1.1
A41: Soe | B41: ="-" -> - | C41: =IFERROR(IF(OR(_Allocations!C12="",_Allocations!C12=0),"-",ROUND(_Allocations!C12,2)),"-") -> 5.46 | D41: =IFERROR(IF(OR(_Allocations!B12="",_Allocations!B12=0),"-",ROUND(_Allocations!B12,2)),"-") -> 13.81 | E41: =IFERROR(IF(_Allocations!D12="","-",ROUND(_Allocations!D12,2)),"-") -> 13.12 | F41: =IFERROR(IF(OR(_Allocations!D12="",_Allocations!B12=0),"-",ROUND(_Allocations!D12/(_Allocations!C12+_Allocations!B12),2)),"-") -> 0.68
A42: Naka | B42: ="-" -> - | C42: =IFERROR(IF(OR(_Allocations!C13="",_Allocations!C13=0),"-",ROUND(_Allocations!C13,2)),"-") -> 4.29 | D42: =IFERROR(IF(OR(_Allocations!B13="",_Allocations!B13=0),"-",ROUND(_Allocations!B13,2)),"-") -> 32.22 | E42: =IFERROR(IF(_Allocations!D13="","-",ROUND(_Allocations!D13,2)),"-") -> 40.28 | F42: =IFERROR(IF(OR(_Allocations!D13="",_Allocations!B13=0),"-",ROUND(_Allocations!D13/(_Allocations!C13+_Allocations!B13),2)),"-") -> 1.1
A43: Tome | B43: ="-" -> - | C43: =IFERROR(IF(OR(_Allocations!C14="",_Allocations!C14=0),"-",ROUND(_Allocations!C14,2)),"-") -> 3.51 | D43: =IFERROR(IF(OR(_Allocations!B14="",_Allocations!B14=0),"-",ROUND(_Allocations!B14,2)),"-") -> 46.04 | E43: =IFERROR(IF(_Allocations!D14="","-",ROUND(_Allocations!D14,2)),"-") -> 66.75 | F43: =IFERROR(IF(OR(_Allocations!D14="",_Allocations!B14=0),"-",ROUND(_Allocations!D14/(_Allocations!C14+_Allocations!B14),2)),"-") -> 1.35
...

Sheet Plan
A1: Brewing Plan | G1: =Recipe!F1 -> v539
A3: KOJI PLAN
A4: Koji method | B4: Select ▽
A5: Koji style (haze) | B5: =IFERROR(IF(Recipe!B8="Select ▽","→ See Recipe",Recipe!B8),"") -> → See Recipe
A6: Koji rice lot | B6: Select ▽
A7: Polish ratio | B7: =IFERROR(IF(B6="Lot A",IF(Recipe!C11="","→ See Recipe",Recipe!C11),IF(B6="Lot B",IF(Recipe!C12="","→ See Recipe",Recipe!C12),IF(B6="Lot C",IF(Recipe!C13="","→ See Recipe",Recipe!C13),IF(B6="Lot D",IF(Recipe!C14="","→ See Recipe",Recipe!C14),"→ Select lot")))),"→ See Recipe") -> → Select lot | C7: %
A8: Time adjustment | B8: =IFERROR(IF(OR(B7="→ See Recipe",B7="→ Select lot"),"",ROUND((70-B7)*0.2,1)),"") | C8: hours
A9: Batch start
A10: Elapsed hours | B10: =IFERROR(IF(OR(B9="",ISBLANK(B9)),"",(NOW()-B9)*24),"") | C10: hours
A12: KOJI WEIGHT PROGRESSION
A13: Dry rice for koji | B13: 1.00×
A14: After soaking | B14: 1.30×
A15: After steaming | B15: 1.40×
A16: After hiki-komi | B16: =IF(OR($B$4="Ueda (Tarai)",$B$4="Ueda Fast"),"1.19× (dried)","1.40×") -> 1.40×
A17: After inoculation | B17: ≈ same
A18: Finished koji (dekoji) | B18: 1.15×
A20: KOJI WORKFLOW
A21: Step | B21: Time | C21: Temp | D21: Target | E21: Weight | F21: Scheduled
A22: =IFERROR(IF(VLOOKUP($B$4,_Lookups!$CB:$CG,2,FALSE())="","",INDIRECT("_Lookups!"&ADDRESS(1+1,VLOOKUP($B$4,_Lookups!$CB:$CG,2,FALSE())))),"") | B22: =IFERROR(IF(VLOOKUP($B$4,_Lookups!$CB:$CG,3,FALSE())="","",IF(INDIRECT("_Lookups!"&ADDRESS(1+1,VLOOKUP($B$4,_Lookups!$CB:$CG,3,FALSE())))="","",IF(INDIRECT("_Lookups!"&ADDRESS(1+1,VLOOKUP($B$4,_Lookups!$CB:$CG,3,FALSE())))<0,INDIRECT("_Lookups!"&ADDRESS(1+1,VLOOKUP($B$4,_Lookups!$CB:$CG,3,FALSE())))&" h","+"&INDIRECT("_Lookups!"&ADDRESS(1+1,VLOOKUP($B$4,_Lookups!$CB:$CG,3,FALSE())))&" h"))),"") | C22: =IFERROR(IF(VLOOKUP($B$4,_Lookups!$CB:$CG,4,FALSE())="","",INDIRECT("_Lookups!"&ADDRESS(1+1,VLOOKUP($B$4,_Lookups!$CB:$CG,4,FALSE())))),"") | D22: =IFERROR(IF(VLOOKUP($B$4,_Lookups!$CB:$CG,5,FALSE())="","",INDIRECT("_Lookups!"&ADDRESS(1+1,VLOOKUP($B$4,_Lookups!$CB:$CG,5,FALSE())))),"") | E22: =IFERROR(IF(A19="","",IF(ISNUMBER(SEARCH("Soak",A19)),TEXT($B$11,"0.00")&" kg",IF(ISNUMBER(SEARCH("Steam",A19)),TEXT($B$12,"0.00")&" kg",IF(ISNUMBER(SEARCH("DRY DOWN",A19)),TEXT($B$13,"0.00")&" kg",IF(ISNUMBER(SEARCH("Dekoji",A19)),TEXT($B$15,"0.00")&" kg",""))))),"") | F22: =IFERROR(IF(OR(A19="",$B$9=""),"",IF(LEFT(B19,1)="+",$B$9+VALUE(SUBSTITUTE(B19," h",""))/24,IF(LEFT(B19,1)="-",$B$9+VALUE(SUBSTITUTE(B19," h",""))/24,$B$9))),"")
A23: =IFERROR(IF(VLOOKUP($B$4,_Lookups!$CB:$CG,2,FALSE())="","",INDIRECT("_Lookups!"&ADDRESS(2+1,VLOOKUP($B$4,_Lookups!$CB:$CG,2,FALSE())))),"") | B23: =IFERROR(IF(VLOOKUP($B$4,_Lookups!$CB:$CG,3,FALSE())="","",IF(INDIRECT("_Lookups!"&ADDRESS(2+1,VLOOKUP($B$4,_Lookups!$CB:$CG,3,FALSE())))="","",IF(INDIRECT("_Lookups!"&ADDRESS(2+1,VLOOKUP($B$4,_Lookups!$CB:$CG,3,FALSE())))<0,INDIRECT("_Lookups!"&ADDRESS(2+1,VLOOKUP($B$4,_Lookups!$CB:$CG,3,FALSE())))&" h","+"&INDIRECT("_Lookups!"&ADDRESS(2+1,VLOOKUP($B$4,_Lookups!$CB:$CG,3,FALSE())))&" h"))),"") | C23: =IFERROR(IF(VLOOKUP($B$4,_Lookups!$CB:$CG,4,FALSE())="","",INDIRECT("_Lookups!"&ADDRESS(2+1,VLOOKUP($B$4,_Lookups!$CB:$CG,4,FALSE())))),"") | D23: =IFERROR(IF(VLOOKUP($B$4,_Lookups!$CB:$CG,5,FALSE())="","",INDIRECT("_Lookups!"&ADDRESS(2+1,VLOOKUP($B$4,_Lookups!$CB:$CG,5,FALSE())))),"") | E23: =IFERROR(IF(A20="","",IF(ISNUMBER(SEARCH("Soak",A20)),TEXT($B$11,"0.00")&" kg",IF(ISNUMBER(SEARCH("Steam",A20)),TEXT($B$12,"0.00")&" kg",IF(ISNUMBER(SEARCH("DRY DOWN",A20)),TEXT($B$13,"0.00")&" kg",IF(ISNUMBER(SEARCH("Dekoji",A20)),TEXT($B$15,"0.00")&" kg",""))))),"") | F23: =IFERROR(IF(OR(A20="",$B$9=""),"",IF(LEFT(B20,1)="+",$B$9+VALUE(SUBSTITUTE(B20," h",""))/24,IF(LEFT(B20,1)="-",$B$9+VALUE(SUBSTITUTE(B20," h",""))/24,$B$9))),"")
A24: =IFERROR(IF(VLOOKUP($B$4,_Lookups!$CB:$CG,2,FALSE())="","",INDIRECT("_Lookups!"&ADDRESS(3+1,VLOOKUP($B$4,_Lookups!$CB:$CG,2,FALSE())))),"") | B24: =IFERROR(IF(VLOOKUP($B$4,_Lookups!$CB:$CG,3,FALSE())="","",IF(INDIRECT("_Lookups!"&ADDRESS(3+1,VLOOKUP($B$4,_Lookups!$CB:$CG,3,FALSE())))="","",IF(INDIRECT("_Lookups!"&ADDRESS(3+1,VLOOKUP($B$4,_Lookups!$CB:$CG,3,FALSE())))<0,INDIRECT("_Lookups!"&ADDRESS(3+1,VLOOKUP($B$4,_Lookups!$CB:$CG,3,FALSE())))&" h","+"&INDIRECT("_Lookups!"&ADDRESS(3+1,VLOOKUP($B$4,_Lookups!$CB:$CG,3,FALSE())))&" h"))),"") | C24: =IFERROR(IF(VLOOKUP($B$4,_Lookups!$CB:$CG,4,FALSE())="","",INDIRECT("_Lookups!"&ADDRESS(3+1,VLOOKUP($B$4,_Lookups!$CB:$CG,4,FALSE())))),"") | D24: =IFERROR(IF(VLOOKUP($B$4,_Lookups!$CB:$CG,5,FALSE())="","",INDIRECT("_Lookups!"&ADDRESS(3+1,VLOOKUP($B$4,_Lookups!$CB:$CG,5,FALSE())))),"") | E24: =IFERROR(IF(A21="","",IF(ISNUMBER(SEARCH("Soak",A21)),TEXT($B$11,"0.00")&" kg",IF(ISNUMBER(SEARCH("Steam",A21)),TEXT($B$12,"0.00")&" kg",IF(ISNUMBER(SEARCH("DRY DOWN",A21)),TEXT($B$13,"0.00")&" kg",IF(ISNUMBER(SEARCH("Dekoji",A21)),TEXT($B$15,"0.00")&" kg",""))))),"") | F24: =IFERROR(IF(OR(A21="",$B$9=""),"",IF(LEFT(B21,1)="+",$B$9+VALUE(SUBSTITUTE(B21," h",""))/24,IF(LEFT(B21,1)="-",$B$9+VALUE(SUBSTITUTE(B21," h",""))/24,$B$9))),"")
A25: =IFERROR(IF(VLOOKUP($B$4,_Lookups!$CB:$CG,2,FALSE())="","",INDIRECT("_Lookups!"&ADDRESS(4+1,VLOOKUP($B$4,_Lookups!$CB:$CG,2,FALSE())))),"") | B25: =IFERROR(IF(VLOOKUP($B$4,_Lookups!$CB:$CG,3,FALSE())="","",IF(INDIRECT("_Lookups!"&ADDRESS(4+1,VLOOKUP($B$4,_Lookups!$CB:$CG,3,FALSE())))="","",IF(INDIRECT("_Lookups!"&ADDRESS(4+1,VLOOKUP($B$4,_Lookups!$CB:$CG,3,FALSE())))<0,INDIRECT("_Lookups!"&ADDRESS(4+1,VLOOKUP($B$4,_Lookups!$CB:$CG,3,FALSE())))&" h","+"&INDIRECT("_Lookups!"&ADDRESS(4+1,VLOOKUP($B$4,_Lookups!$CB:$CG,3,FALSE())))&" h"))),"") | C25: =IFERROR(IF(VLOOKUP($B$4,_Lookups!$CB:$CG,4,FALSE())="","",INDIRECT("_Lookups!"&ADDRESS(4+1,VLOOKUP($B$4,_Lookups!$CB:$CG,4,FALSE())))),"") | D25: =IFERROR(IF(VLOOKUP($B$4,_Lookups!$CB:$CG,5,FALSE())="","",INDIRECT("_Lookups!"&ADDRESS(4+1,VLOOKUP($B$4,_Lookups!$CB:$CG,5,FALSE())))),"") | E25: =IFERROR(IF(A22="","",IF(ISNUMBER(SEARCH("Soak",A22)),TEXT($B$11,"0.00")&" kg",IF(ISNUMBER(SEARCH("Steam",A22)),TEXT($B$12,"0.00")&" kg",IF(ISNUMBER(SEARCH("DRY DOWN",A22)),TEXT($B$13,"0.00")&" kg",IF(ISNUMBER(SEARCH("Dekoji",A22)),TEXT($B$15,"0.00")&" kg",""))))),"") | F25: =IFERROR(IF(OR(A22="",$B$9=""),"",IF(LEFT(B22,1)="+",$B$9+VALUE(SUBSTITUTE(B22," h",""))/24,IF(LEFT(B22,1)="-",$B$9+VALUE(SUBSTITUTE(B22," h",""))/24,$B$9))),"")
A26: =IFERROR(IF(VLOOKUP($B$4,_Lookups!$CB:$CG,2,FALSE())="","",INDIRECT("_Lookups!"&ADDRESS(5+1,VLOOKUP($B$4,_Lookups!$CB:$CG,2,FALSE())))),"") | B26: =IFERROR(IF(VLOOKUP($B$4,_Lookups!$CB:$CG,3,FALSE())="","",IF(INDIRECT("_Lookups!"&ADDRESS(5+1,VLOOKUP($B$4,_Lookups!$CB:$CG,3,FALSE())))="","",IF(INDIRECT("_Lookups!"&ADDRESS(5+1,VLOOKUP($B$4,_Lookups!$CB:$CG,3,FALSE())))<0,INDIRECT("_Lookups!"&ADDRESS(5+1,VLOOKUP($B$4,_Lookups!$CB:$CG,3,FALSE())))&" h","+"&INDIRECT("_Lookups!"&ADDRESS(5+1,VLOOKUP($B$4,_Lookups!$CB:$CG,3,FALSE())))&" h"))),"") | C26: =IFERROR(IF(VLOOKUP($B$4,_Lookups!$CB:$CG,4,FALSE())="","",INDIRECT("_Lookups!"&ADDRESS(5+1,VLOOKUP($B$4,_Lookups!$CB:$CG,4,FALSE())))),"") | D26: =IFERROR(IF(VLOOKUP($B$4,_Lookups!$CB:$CG,5,FALSE())="","",INDIRECT("_Lookups!"&ADDRESS(5+1,VLOOKUP($B$4,_Lookups!$CB:$CG,5,FALSE())))),"") | E26: =IFERROR(IF(A23="","",IF(ISNUMBER(SEARCH("Soak",A23)),TEXT($B$11,"0.00")&" kg",IF(ISNUMBER(SEARCH("Steam",A23)),TEXT($B$12,"0.00")&" kg",IF(ISNUMBER(SEARCH("DRY DOWN",A23)),TEXT($B$13,"0.00")&" kg",IF(ISNUMBER(SEARCH("Dekoji",A23)),TEXT($B$15,"0.00")&" kg",""))))),"") | F26: =IFERROR(IF(OR(A23="",$B$9=""),"",IF(LEFT(B23,1)="+",$B$9+VALUE(SUBSTITUTE(B23," h",""))/24,IF(LEFT(B23,1)="-",$B$9+VALUE(SUBSTITUTE(B23," h",""))/24,$B$9))),"")
A27: =IFERROR(IF(VLOOKUP($B$4,_Lookups!$CB:$CG,2,FALSE())="","",INDIRECT("_Lookups!"&ADDRESS(6+1,VLOOKUP($B$4,_Lookups!$CB:$CG,2,FALSE())))),"") | B27: =IFERROR(IF(VLOOKUP($B$4,_Lookups!$CB:$CG,3,FALSE())="","",IF(INDIRECT("_Lookups!"&ADDRESS(6+1,VLOOKUP($B$4,_Lookups!$CB:$CG,3,FALSE())))="","",IF(INDIRECT("_Lookups!"&ADDRESS(6+1,VLOOKUP($B$4,_Lookups!$CB:$CG,3,FALSE())))<0,INDIRECT("_Lookups!"&ADDRESS(6+1,VLOOKUP($B$4,_Lookups!$CB:$CG,3,FALSE())))&" h","+"&INDIRECT("_Lookups!"&ADDRESS(6+1,VLOOKUP($B$4,_Lookups!$CB:$CG,3,FALSE())))&" h"))),"") | C27: =IFERROR(IF(VLOOKUP($B$4,_Lookups!$CB:$CG,4,FALSE())="","",INDIRECT("_Lookups!"&ADDRESS(6+1,VLOOKUP($B$4,_Lookups!$CB:$CG,4,FALSE())))),"") | D27: =IFERROR(IF(VLOOKUP($B$4,_Lookups!$CB:$CG,5,FALSE())="","",INDIRECT("_Lookups!"&ADDRESS(6+1,VLOOKUP($B$4,_Lookups!$CB:$CG,5,FALSE())))),"") | E27: =IFERROR(IF(A24="","",IF(ISNUMBER(SEARCH("Soak",A24)),TEXT($B$11,"0.00")&" kg",IF(ISNUMBER(SEARCH("Steam",A24)),TEXT($B$12,"0.00")&" kg",IF(ISNUMBER(SEARCH("DRY DOWN",A24)),TEXT($B$13,"0.00")&" kg",IF(ISNUMBER(SEARCH("Dekoji",A24)),TEXT($B$15,"0.00")&" kg",""))))),"") | F27: =IFERROR(IF(OR(A24="",$B$9=""),"",IF(LEFT(B24,1)="+",$B$9+VALUE(SUBSTITUTE(B24," h",""))/24,IF(LEFT(B24,1)="-",$B$9+VALUE(SUBSTITUTE(B24," h",""))/24,$B$9))),"")
A28: =IFERROR(IF(VLOOKUP($B$4,_Lookups!$CB:$CG,2,FALSE())="","",INDIRECT("_Lookups!"&ADDRESS(7+1,VLOOKUP($B$4,_Lookups!$CB:$CG,2,FALSE())))),"") | B28: =IFERROR(IF(VLOOKUP($B$4,_Lookups!$CB:$CG,3,FALSE())="","",IF(INDIRECT("_Lookups!"&ADDRESS(7+1,VLOOKUP($B$4,_Lookups!$CB:$CG,3,FALSE())))="","",IF(INDIRECT("_Lookups!"&ADDRESS(7+1,VLOOKUP($B$4,_Lookups!$CB:$CG,3,FALSE())))<0,INDIRECT("_Lookups!"&ADDRESS(7+1,VLOOKUP($B$4,_Lookups!$CB:$CG,3,FALSE())))&" h","+"&INDIRECT("_Lookups!"&ADDRESS(7+1,VLOOKUP($B$4,_Lookups!$CB:$CG,3,FALSE())))&" h"))),"") | C28: =IFERROR(IF(VLOOKUP($B$4,_Lookups!$CB:$CG,4,FALSE())="","",INDIRECT("_Lookups!"&ADDRESS(7+1,VLOOKUP($B$4,_Lookups!$CB:$CG,4,FALSE())))),"") | D28: =IFERROR(IF(VLOOKUP($B$4,_Lookups!$CB:$CG,5,FALSE())="","",INDIRECT("_Lookups!"&ADDRESS(7+1,VLOOKUP($B$4,_Lookups!$CB:$CG,5,FALSE())))),"") | E28: =IFERROR(IF(A25="","",IF(ISNUMBER(SEARCH("Soak",A25)),TEXT($B$11,"0.00")&" kg",IF(ISNUMBER(SEARCH("Steam",A25)),TEXT($B$12,"0.00")&" kg",IF(ISNUMBER(SEARCH("DRY DOWN",A25)),TEXT($B$13,"0.00")&" kg",IF(ISNUMBER(SEARCH("Dekoji",A25)),TEXT($B$15,"0.00")&" kg",""))))),"") | F28: =IFERROR(IF(OR(A25="",$B$9=""),"",IF(LEFT(B25,1)="+",$B$9+VALUE(SUBSTITUTE(B25," h",""))/24,IF(LEFT(B25,1)="-",$B$9+VALUE(SUBSTITUTE(B25," h",""))/24,$B$9))),"")
A29: =IFERROR(IF(VLOOKUP($B$4,_Lookups!$CB:$CG,2,FALSE())="","",INDIRECT("_Lookups!"&ADDRESS(8+1,VLOOKUP($B$4,_Lookups!$CB:$CG,2,FALSE())))),"") | B29: =IFERROR(IF(VLOOKUP($B$4,_Lookups!$CB:$CG,3,FALSE())="","",IF(INDIRECT("_Lookups!"&ADDRESS(8+1,VLOOKUP($B$4,_Lookups!$CB:$CG,3,FALSE())))="","",IF(INDIRECT("_Lookups!"&ADDRESS(8+1,VLOOKUP($B$4,_Lookups!$CB:$CG,3,FALSE())))<0,INDIRECT("_Lookups!"&ADDRESS(8+1,VLOOKUP($B$4,_Lookups!$CB:$CG,3,FALSE())))&" h","+"&INDIRECT("_Lookups!"&ADDRESS(8+1,VLOOKUP($B$4,_Lookups!$CB:$CG,3,FALSE())))&" h"))),"") | C29: =IFERROR(IF(VLOOKUP($B$4,_Lookups!$CB:$CG,4,FALSE())="","",INDIRECT("_Lookups!"&ADDRESS(8+1,VLOOKUP($B$4,_Lookups!$CB:$CG,4,FALSE())))),"") | D29: =IFERROR(IF(VLOOKUP($B$4,_Lookups!$CB:$CG,5,FALSE())="","",INDIRECT("_Lookups!"&ADDRESS(8+1,VLOOKUP($B$4,_Lookups!$CB:$CG,5,FALSE())))),"") | E29: =IFERROR(IF(A26="","",IF(ISNUMBER(SEARCH("Soak",A26)),TEXT($B$11,"0.00")&" kg",IF(ISNUMBER(SEARCH("Steam",A26)),TEXT($B$12,"0.00")&" kg",IF(ISNUMBER(SEARCH("DRY DOWN",A26)),TEXT($B$13,"0.00")&" kg",IF(ISNUMBER(SEARCH("Dekoji",A26)),TEXT($B$15,"0.00")&" kg",""))))),"") | F29: =IFERROR(IF(OR(A26="",$B$9=""),"",IF(LEFT(B26,1)="+",$B$9+VALUE(SUBSTITUTE(B26," h",""))/24,IF(LEFT(B26,1)="-",$B$9+VALUE(SUBSTITUTE(B26," h",""))/24,$B$9))),"")
A30: =IFERROR(IF(VLOOKUP($B$4,_Lookups!$CB:$CG,2,FALSE())="","",INDIRECT("_Lookups!"&ADDRESS(9+1,VLOOKUP($B$4,_Lookups!$CB:$CG,2,FALSE())))),"") | B30: =IFERROR(IF(VLOOKUP($B$4,_Lookups!$CB:$CG,3,FALSE())="","",IF(INDIRECT("_Lookups!"&ADDRESS(9+1,VLOOKUP($B$4,_Lookups!$CB:$CG,3,FALSE())))="","",IF(INDIRECT("_Lookups!"&ADDRESS(9+1,VLOOKUP($B$4,_Lookups!$CB:$CG,3,FALSE())))<0,INDIRECT("_Lookups!"&ADDRESS(9+1,VLOOKUP($B$4,_Lookups!$CB:$CG,3,FALSE())))&" h","+"&INDIRECT("_Lookups!"&ADDRESS(9+1,VLOOKUP($B$4,_Lookups!$CB:$CG,3,FALSE())))&" h"))),"") | C30: =IFERROR(IF(VLOOKUP($B$4,_Lookups!$CB:$CG,4,FALSE())="","",INDIRECT("_Lookups!"&ADDRESS(9+1,VLOOKUP($B$4,_Lookups!$CB:$CG,4,FALSE())))),"") | D30: =IFERROR(IF(VLOOKUP($B$4,_Lookups!$CB:$CG,5,FALSE())="","",INDIRECT("_Lookups!"&ADDRESS(9+1,VLOOKUP($B$4,_Lookups!$CB:$CG,5,FALSE())))),"") | E30: =IFERROR(IF(A27="","",IF(ISNUMBER(SEARCH("Soak",A27)),TEXT($B$11,"0.00")&" kg",IF(ISNUMBER(SEARCH("Steam",A27)),TEXT($B$12,"0.00")&" kg",IF(ISNUMBER(SEARCH("DRY DOWN",A27)),TEXT($B$13,"0.00")&" kg",IF(ISNUMBER(SEARCH("Dekoji",A27)),TEXT($B$15,"0.00")&" kg",""))))),"") | F30: =IFERROR(IF(OR(A27="",$B$9=""),"",IF(LEFT(B27,1)="+",$B$9+VALUE(SUBSTITUTE(B27," h",""))/24,IF(LEFT(B27,1)="-",$B$9+VALUE(SUBSTITUTE(B27," h",""))/24,$B$9))),"")
A31: =IFERROR(IF(VLOOKUP($B$4,_Lookups!$CB:$CG,2,FALSE())="","",INDIRECT("_Lookups!"&ADDRESS(10+1,VLOOKUP($B$4,_Lookups!$CB:$CG,2,FALSE())))),"") | B31: =IFERROR(IF(VLOOKUP($B$4,_Lookups!$CB:$CG,3,FALSE())="","",IF(INDIRECT("_Lookups!"&ADDRESS(10+1,VLOOKUP($B$4,_Lookups!$CB:$CG,3,FALSE())))="","",IF(INDIRECT("_Lookups!"&ADDRESS(10+1,VLOOKUP($B$4,_Lookups!$CB:$CG,3,FALSE())))<0,INDIRECT("_Lookups!"&ADDRESS(10+1,VLOOKUP($B$4,_Lookups!$CB:$CG,3,FALSE())))&" h","+"&INDIRECT("_Lookups!"&ADDRESS(10+1,VLOOKUP($B$4,_Lookups!$CB:$CG,3,FALSE())))&" h"))),"") | C31: =IFERROR(IF(VLOOKUP($B$4,_Lookups!$CB:$CG,4,FALSE())="","",INDIRECT("_Lookups!"&ADDRESS(10+1,VLOOKUP($B$4,_Lookups!$CB:$CG,4,FALSE())))),"") | D31: =IFERROR(IF(VLOOKUP($B$4,_Lookups!$CB:$CG,5,FALSE())="","",INDIRECT("_Lookups!"&ADDRESS(10+1,VLOOKUP($B$4,_Lookups!$CB:$CG,5,FALSE())))),"") | E31: =IFERROR(IF(A28="","",IF(ISNUMBER(SEARCH("Soak",A28)),TEXT($B$11,"0.00")&" kg",IF(ISNUMBER(SEARCH("Steam",A28)),TEXT($B$12,"0.00")&" kg",IF(ISNUMBER(SEARCH("DRY DOWN",A28)),TEXT($B$13,"0.00")&" kg",IF(ISNUMBER(SEARCH("Dekoji",A28)),TEXT($B$15,"0.00")&" kg",""))))),"") | F31: =IFERROR(IF(OR(A28="",$B$9=""),"",IF(LEFT(B28,1)="+",$B$9+VALUE(SUBSTITUTE(B28," h",""))/24,IF(LEFT(B28,1)="-",$B$9+VALUE(SUBSTITUTE(B28," h",""))/24,$B$9))),"")
A32: =IFERROR(IF(VLOOKUP($B$4,_Lookups!$CB:$CG,2,FALSE())="","",INDIRECT("_Lookups!"&ADDRESS(11+1,VLOOKUP($B$4,_Lookups!$CB:$CG,2,FALSE())))),"")
A33: =IFERROR(IF(VLOOKUP($B$4,_Lookups!$CB:$CG,2,FALSE())="","",INDIRECT("_Lookups!"&ADDRESS(12+1,VLOOKUP($B$4,_Lookups!$CB:$CG,2,FALSE())))),"") | B33: =IFERROR(IF(VLOOKUP($B$4,_Lookups!$CB:$CG,3,FALSE())="","",IF(INDIRECT("_Lookups!"&ADDRESS(12+1,VLOOKUP($B$4,_Lookups!$CB:$CG,3,FALSE())))="","",IF(INDIRECT("_Lookups!"&ADDRESS(12+1,VLOOKUP($B$4,_Lookups!$CB:$CG,3,FALSE())))<0,INDIRECT("_Lookups!"&ADDRESS(12+1,VLOOKUP($B$4,_Lookups!$CB:$CG,3,FALSE())))&" h","+"&INDIRECT("_Lookups!"&ADDRESS(12+1,VLOOKUP($B$4,_Lookups!$CB:$CG,3,FALSE())))&" h"))),"") | C33: =IFERROR(IF(VLOOKUP($B$4,_Lookups!$CB:$CG,4,FALSE())="","",INDIRECT("_Lookups!"&ADDRESS(12+1,VLOOKUP($B$4,_Lookups!$CB:$CG,4,FALSE())))),"") | D33: =IFERROR(IF(VLOOKUP($B$4,_Lookups!$CB:$CG,5,FALSE())="","",INDIRECT("_Lookups!"&ADDRESS(12+1,VLOOKUP($B$4,_Lookups!$CB:$CG,5,FALSE())))),"") | E33: =IFERROR(IF(A30="","",IF(ISNUMBER(SEARCH("Soak",A30)),TEXT($B$11,"0.00")&" kg",IF(ISNUMBER(SEARCH("Steam",A30)),TEXT($B$12,"0.00")&" kg",IF(ISNUMBER(SEARCH("DRY DOWN",A30)),TEXT($B$13,"0.00")&" kg",IF(ISNUMBER(SEARCH("Dekoji",A30)),TEXT($B$15,"0.00")&" kg",""))))),"") | F33: =IFERROR(IF(OR(A30="",$B$6=""),"",IF(LEFT(B30,1)="+",$B$6+VALUE(SUBSTITUTE(B30," h",""))/24,IF(LEFT(B30,1)="-",$B$6+VALUE(SUBSTITUTE(B30," h",""))/24,$B$6))),"")
A35: MOTO PLAN
A36: Moto type | B36: Select ▽
A37: Moto start
A38: Elapsed hours | B38: =IFERROR(IF(OR(B37="",ISBLANK(B37)),"",(NOW()-B37)*24),"") | C38: hours
A40: MOTO QUANTITIES
A41: Total moto rice (kg) | B41: =IFERROR(_Allocations!B11,"") -> 6.93
A42: Moto koji (kg) | B42: =IFERROR(_Allocations!C11,"") -> 2.2869
A43: Moto water (L) | B43: =IFERROR(_Allocations!D11,"") -> 7.623
A44: Moto kakemai (kg) | B44: =IFERROR(_Allocations!B24,"") -> 4.6431
A46: MOTO WORKFLOW
...

Sheet Quick Calc
A1: QUICK CALCULATORS
A3: RICE WEIGHT CONVERSIONS | D3: DILUTION CALCULATOR
A4: Steamed rice (kg) | D4: Current ABV (%)
A5: → Dry rice was (kg) | B5: =IFERROR(IF(B4="","",ROUND(B4/1.4,3)),"") | C5: ÷ 1.40 | D5: Current volume (L)
A6: Soaked rice (kg) | D6: Target ABV (%)
A7: → Dry rice was (kg) | B7: =IFERROR(IF(B6="","",ROUND(B6/1.3,3)),"") | C7: ÷ 1.30 | D7: → Final volume (L) | E7: =IFERROR(IF(OR(E4="",E5="",E6=""),"",ROUND(E4*E5/E6,2)),"") | F7: ABV₁ × V₁ / ABV₂
A8: Dry rice (kg) | D8: → Water to add (L) | E8: =IFERROR(IF(OR(E7="",E5=""),"",ROUND(E7-E5,2)),"") | F8: Final - Current
A9: After soak (kg)
A10: → Absorption % | B10: =IFERROR(IF(OR(B8="",B9=""),"",ROUND((B9-B8)/B8*100,1)),"") | C10: (after-before)/before × 100 | D10: SMV (NIHONSHUDO)
D11: Specific gravity
A12: UEDA METHOD DRY-DOWN | D12: → SMV (日本酒度) | E12: =IFERROR(IF(E11="","",ROUND((1/E11-1)*1443,0)),"") | F12: (1/SG - 1) × 1443
A13: Steamed rice (kg)
A14: → Target hiki-komi (kg) | B14: =IFERROR(IF(B13="","",ROUND(B13*0.85,3)),"") | C14: × 0.85 | D14: TEMPERATURE
A15: → Water to remove (kg) | B15: =IFERROR(IF(B13="","",ROUND(B13*0.15,3)),"") | C15: × 0.15 | D15: Celsius (°C)
A16: Drying temp (°C) | B16: 40 | C16: rec: 38-42 | D16: → Fahrenheit (°F) | E16: =IFERROR(IF(E15="","",ROUND(E15*9/5+32,1)),"") | F16: °C × 9/5 + 32
A17: Humidity (% RH) | B17: 45 | C17: rec: <50%
A18: → Est. dry time (min) | B18: =IFERROR(IF(OR(B13="",B16="",B17=""),"",IF(B17>=60,"Too humid",IF(B16<35,"Too cold",ROUND(150/(2.7*(1+0.05*(B16-40))*((65-B17)/25)),0)))),"") | C18: ≈55 min at 40°C/40%RH
A19: KOJI TRAY COUNT | D19: Fahrenheit (°F)
A20: Pre-inoc weight (kg) | D20: → Celsius (°C)
A21: Tray capacity (kg) | B21: 1.5
A22: → Trays needed | B22: =IFERROR(IF(OR(B20="",B21=""),"",CEILING(B20/B21,1)),"") | C22: CEILING(weight/capacity) | D22: YIELD ESTIMATE
D23: Total dry rice (kg)
D24: Target ABV (%) | E24: 15
D25: → Genshu yield (L) | E25: =IFERROR(IF(OR(E21="",E22=""),"",ROUND(E21*1.3*0.63*(18/E22),1)),"") | F25: rice × 1.3 × 0.63 × (18/ABV)
A29: LACTIC ACID (SOKUJO) | D29: MOROMI PROGRESS
A30: Moto water (L) | D30: Current Baumé (°Bé)
A31: Acid concentration (%) | B31: 88 | D31: Starting Baumé (°Bé) | E31: 14
A32: → mL to add | B32: =IFERROR(IF(OR(B30="",B31=""),"",ROUND((B30*0.4)/(B31/100),2)),"") | C32: 0.4% of water ÷ concentration | D32: → % Complete | E32: =IFERROR(IF(OR(E28="",E29=""),"",ROUND((E29-E28)/E29*100,0)&"%"),"") | F32: (start - current) / start × 100
A34: BAUMÉ ↔ SG | D34: Days since Soe
A35: Baumé (°Bé) | D35: → Est. ABV (%)
A36: → Specific Gravity | B36: =IFERROR(IF(B35="","",ROUND(145/(145-B35),4)),"") | C36: 145 / (145 - Bé)
A37: Specific Gravity | D37: RICE PROTEIN ESTIMATE
A38: → Baumé (°Bé) | B38: =IFERROR(IF(B37="","",ROUND(145-(145/B37),1)),"") | C38: 145 - (145 / SG) | D38: Polish ratio (%)
D39: Original protein (%) | E39: 6.5
D40: → Est. remaining protein (%)
A42: BRIX CONVERSIONS | D42: WATER RATIO
A43: Brix (°Bx) | D43: Total dry rice (kg)
A44: → Baumé (°Bé) | B44: =IFERROR(IF(B43="","",ROUND(B43/1.8,1)),"") | C44: Brix / 1.8 | D44: Water ratio | E44: 1.3
A45: → Specific Gravity | D45: → Total water (L)
A47: KOJI SPORE DOSING (種付け) | D47: PRESSING YIELD
...

Sheet Koji Ferments
A1: Koji Ferments Calculator
A3: SHIO KOJI (塩麹) — Salt Koji
A5: Versatile seasoning paste. Koji enzymes tenderize protein and develop umami. Use as marinade, seasoning, or salt replacement.
A7: INPUTS
A8: Target shio koji (kg)
A9: Salt ratio (%) | B9: 13
A11: CALCULATED
A12: Rice koji (kg) | B12: =IFERROR(B8*0.67,"") -> 0
A13: Salt (g) | B13: =IFERROR(B8*B9*10,"") -> 0
A14: Water (mL) | B14: =IFERROR(B8*200,"") -> 0
A16: PROCESS
A17: Mix method | B17: Combine all, massage daily
A18: Fermentation | B18: 7-14 days at 20-25°C
A19: Storage | B19: Refrigerate, use within 6 months
A22: AMAZAKE (甘酒) — Sweet Rice Drink
A24: Traditional sweet drink made by koji saccharification of rice. No alcohol (unless fermented further). High in glucose, B vitamins, and koji enzymes.
A26: INPUTS
A27: Target amazake (L)
A29: CALCULATED
A30: Rice, dry (kg) | B30: =IFERROR(B27*0.25,"") -> 0
A31: Rice koji (kg) | B31: =IFERROR(B27*0.25,"") -> 0
A32: Water (L) | B32: =IFERROR(B27*0.6,"") -> 0
A34: PROCESS
A35: Cook rice | B35: Soft, slightly wet
A36: Cool to | B36: 60°C
A37: Mix koji | B37: Combine, hold 55-60°C
A38: Saccharification | B38: 8-12 hours at 55-60°C
A39: Storage | B39: Refrigerate 1 week, freeze longer
A42: MISO (味噌) — Fermented Soybean Paste
A44: Protein-rich paste fermented 3 months to 3+ years. Koji enzymes break down soy protein into amino acids (umami). Ratio of koji to soy determines sweetness vs. depth.
A46: INPUTS
A47: Target miso (kg)
A48: Koji ratio | B48: 1
A49: Salt (%) | B49: 12
A51: CALCULATED
A52: Soybeans, dry (kg) | B52: =IFERROR(B47/(1+B48+B49/100+0.5),"") -> 0
A53: Rice koji (kg) | B53: =IFERROR(B52*B48,"") -> 0
A54: Salt (kg) | B54: =IFERROR(B47*B49/100,"") -> 0
A55: Soy cooking liquid (mL) | B55: =IFERROR(B52*200,"") -> 0
A57: MISO STYLES
...

Sheet Soak Calc
A1: Soak Time Calculator
A3: SOAK PARAMETERS
A4: Wash water temp | B4: 10 | C4: °C | D4: Cold water slows absorption during wash
A5: Wash time | B5: 3 | C5: min | D5: Gentle motion only to prevent cracking
A6: Soak water temp | B6: 10 | C6: °C | D6: Match wash temp; colder = more control
A7: Actual soak time | C7: min | D7: Record actual - compare to recommended below
A8: Rice storage temp | B8: 15 | C8: °C | D8: Match both wash & soak temps to this
A9: Cracking risk | B9: =IFERROR(IF(OR(B4="",B6="",B8=""),"",MAX(ABS(B4-B8),ABS(B6-B8))),"") -> 5 | C9: °C max | D9: =IFERROR(IF(B9="","",IF(B9>10,"⚠ HIGH - grains will crack!",IF(B9>5,"Caution - handle gently","OK - safe"))),"") -> OK - safe
A10: Rice lot | B10: Lot A
A11: Polish ratio | B11: =IFERROR(IF(B10="Lot A",IF(Recipe!C11="","→ See Recipe",Recipe!C11),IF(B10="Lot B",IF(Recipe!C12="","→ See Recipe",Recipe!C12),IF(B10="Lot C",IF(Recipe!C13="","→ See Recipe",Recipe!C13),IF(B10="Lot D",IF(Recipe!C14="","→ See Recipe",Recipe!C14),"→ See Recipe")))),"→ See Recipe") -> → See Recipe | C11: %
A12: Variety | B12: =IFERROR(IF(B10="Lot A",IF(OR(Recipe!B11="",Recipe!B11="Select ▽"),"→ See Recipe",Recipe!B11),IF(B10="Lot B",IF(OR(Recipe!B12="",Recipe!B12="Select ▽"),"→ See Recipe",Recipe!B12),IF(B10="Lot C",IF(OR(Recipe!B13="",Recipe!B13="Select ▽"),"→ See Recipe",Recipe!B13),IF(B10="Lot D",IF(OR(Recipe!B14="",Recipe!B14="Select ▽"),"→ See Recipe",Recipe!B14),"→ See Recipe")))),"→ See Recipe") -> → See Recipe
A14: CALCULATED TARGETS
A15: Base soak time | B15: =IFERROR(IF(B11="","",IF(B11>=85,ROUND(90+(100-B11)*3,0),IF(B11>=70,ROUND(30+(85-B11)*2,0),IF(B11>=60,ROUND(10+(70-B11)*2,0),IF(B11>=50,ROUND(8+(60-B11)*0.4,0),IF(B11>=40,ROUND(4+(50-B11)*0.4,0),ROUND(1+(40-B11)*0.3,0))))))),"—") -> — | C15: min
A16: Temp adjustment | B16: =IFERROR(IF(OR(B6="",B11=""),"",ROUND((15-B6)*0.5,1)),"—") -> 2.5 | C16: min | D16: 15°C baseline; colder = longer
A17: Recommended soak | B17: =IFERROR(IF(B15="","",MAX(1,ROUND(B15+B16,0))),"—") -> — | C17: min | D17: =IFERROR(IF(OR(B7="",B17=""),"",IF(B7>B17*1.2,"⚠ Over-soaked!",IF(B7<B17*0.8,"⚠ Under-soaked","✓ Good"))),"")
A18: Target absorption | B18: =IFERROR(IF(B11="","",ROUND(34-(100-B11)*0.15,0)),"—") -> — | C18: % | D18: Weight gain from dry rice
A19: Karashi rest | B19: 60 | C19: min | D19: 45 min minimum; some brewers do 24 hrs
A20: Fat extraction | B20: =IFERROR(IF(B4="","",IF(B4<10,"Low",IF(B4<15,"Moderate","Good"))),"—") -> Moderate | D20: Warmer wash = more lipid removal
A21: FAT EXTRACTION GUIDE
A22: Water temp | B22: Time needed | C22: Fats extracted | D22: Polish guidance
A23: 5-8°C | B23: 10+ min | C23: Linoleic only (mp -5°C) | D23: ≤50% daiginjo - timing control critical
A24: 8-12°C | B24: 5-8 min | C24: Linoleic + partial oleic | D24: 50-60% ginjo - balance of control & extraction
A25: 12-15°C | B25: 3-5 min | C25: Linoleic + oleic (mp 13°C) | D25: 70% junmai - good fat removal
A26: 15-18°C | B26: 3-5 min | C26: Most unsaturated (75%) | D26: 80% standard - thorough extraction
A27: 18-25°C | B27: 2-3 min | C27: All except palmitic (mp 63°C) | D27: 90% table rice - fast extraction OK
A28: FAT TYPES IN NUKA:
A29: • Oleic (38-44%, mp 13°C) - suppresses ester formation if not removed
A30: • Linoleic (28-35%, mp -5°C) - always mobile in cold water, extracts easily
A31: REFERENCE TABLE
A32: Polish % | B32: Soak time | C32: Target % | D32: Grade | E32: Critical window
A33: 90 | B33: 60-120 | C33: 30-32 | D33: Futsu-shu | E33: Wide - forgiving
A34: 80 | B34: 40-60 | C34: 29-31 | D34: Junmai | E34: Moderate
A35: 70 | B35: 20-40 | C35: 28-30 | D35: Tokubetsu | E35: Moderate
A36: 60 | B36: 10-20 | C36: 26-28 | D36: Ginjo | E36: 1-3 min critical
A37: 50 | B37: 5-15 | C37: 24-26 | D37: Daiginjo | E37: Seconds matter
A38: 40 | B38: 3-8 | C38: 22-24 | D38: Competition | E38: Stopwatch + gentle handling
A39: 35 | B39: 1-5 | C39: 20-22 | D39: Ultra-polish | E39: Extreme precision + fragile!
A41: SOAK TEST LOG
A42: Sample | B42: Dry (g) | C42: Wet (g) | D42: Gain % | E42: Time (min) | F42: Status | G42: Notes
A43: 1 | D43: =IFERROR(IF(B43="","",ROUND((C43-B43)/B43*100,1)),"") | F43: =IFERROR(IF(D43="","",IF(ABS(D43-$B$18)<=2,"OK",IF(D43<$B$18,"Under","Over"))),"")
...

Sheet Yeast Calc
A1: Yeast Calculator
A3: INPUTS | B3: Value | C3: Units | D3: Notes
A4: Target volume for pitching (L) | B4: =IF(Recipe!B56="",0,Recipe!B56) -> 10.0485 | C4: L | D4: Default: theoretical moromi volume from Recipe; override if needed.
A5: Pitch rate | B5: =_Constants!B10 -> 10 | C5: M cells/mL | D5: Million cells per mL; typical range 5–15.
A6: Dry yeast cells per g | B6: =_Constants!B11 -> 10000000000 | C6: cells/g | D6: Check spec sheet for your yeast.
A7: Liquid yeast cells per mL | B7: =_Constants!B12 -> 100000000 | C7: cells/mL | D7: Assumed for liquid culture or pouch.
A8: Liquid yeast pouch volume | B8: =_Constants!B13 -> 100 | C8: mL | D8: Volume of one pouch or pack.
A10: CALCULATED OUTPUTS
A11: Total cells needed | B11: =IF(B4="","",B4*1000*B5*1000000) -> 100485000000 | C11: cells | D11: Volume (L) × 1000 mL/L × pitch rate (M/mL) × 1E6.
A12: Dry yeast needed | B12: =IF(B6>0,IF(B11="","",B11/B6),"") -> 10.0485 | C12: g | D12: Total cells ÷ cells per gram.
A13: Liquid yeast volume | B13: =IF(B7>0,IF(B11="","",B11/B7),"") -> 1004.85 | C13: mL | D13: Total cells ÷ cells per mL.
A14: Liquid yeast pouches | B14: =IF(AND(B8>0,B13<>""),B13/B8,"") -> 10.0485 | C14: pouches | D14: Liquid volume ÷ pouch volume; round as needed.
A16: NITROGEN ADJUSTMENT
A17: Vigor factor | B17: =IF(_Allocations!B38="",1,_Allocations!B38) -> 1
A18: Adjusted pitch rate | B18: =IF(B5="","",ROUND(B5/B17,1)) -> 10
A19: Adjusted cells needed | B19: =IF(B4="","",B4*1000*B18*1000000) -> 100485000000
A20: Adjusted dry yeast (g) | B20: =IF(B6>0,IF(B19="","",B19/B6),"") -> 10.0485
A21: Adjustment reason | B21: =IF(B17="","",IF(B17>1.1,"↓ Reduce pitch - nitrogen-rich environment",IF(B17<0.9,"↑ Increase pitch - low nitrogen environment","Standard pitch OK"))) -> Standard pitch OK
A23: NITROGEN GUIDANCE
A24: Rice seimaibuai | B24: =IF(_Inputs!B24="","(Set in Recipe)",_Inputs!B24&"%") -> 0%
A25: Amino tendency | B25: =_Allocations!B35
A26: Expected fermentation | B26: =_Allocations!B39
A28: Note: Low-polish sake (90%+) paradoxically produces
A29: LOWER amino acidity because yeast uptake is 1.5x higher.
A30: Peak amino release occurs around 70-75% seimaibuai.

Sheet Pasteurization Calc
A1: Pasteurization Calculator | F1: v539
A3: INPUTS
A4: Goal | B4: Select
A5: Package | B5: Select
A6: Method | B6: Select
A7: ABV (%)
A8: Pasteurization strategy | B8: Select
A9: Cooling | B9: Select
A10: Storage intent | B10: Select
A11: Storage temp | B11: Select
A12: Total bottles
A13: Bottles per batch
A14: Starting temp (C) | B14: 20
A16: YOUR PROCESS
A17: 1. Heat to | B17: =IFERROR(IF(B4="Select","Select goal above",IF(ISNUMBER(SEARCH("Yeast only",B4)),"60°C core temp",IF(ISNUMBER(SEARCH("Standard",B4)),"65°C core temp",IF(ISNUMBER(SEARCH("Full",B4)),"65°C core temp (do 2x)","65°C core temp")))),"") -> Select goal above
A18: 2. Hold | B18: =IFERROR(IF(B4="Select","Select goal above","30 seconds minimum"),"") -> Select goal above
A19: 3. Cool | B19: =IFERROR(IF(B9="Select","Select cooling above",IF(ISNUMBER(SEARCH("Ice",B9)),"Ice bath until <30°C",IF(ISNUMBER(SEARCH("Cold water",B9)),"Cold water until <30°C",IF(ISNUMBER(SEARCH("Air",B9)),"Air cool (SLOW - adds PU)","Plate HX inline")))),"") -> Select cooling above
A20: 4. Batches needed | B20: =IFERROR(IF(OR(B12="",B13=""),"Enter quantities above",CEILING(B12/B13,1)),"") -> Enter quantities above
A21: 5. Time per batch | B21: =IFERROR(IF(B5="Select","Select package above",IF(ISNUMBER(SEARCH("1.8",B5)),"~70 min",IF(ISNUMBER(SEARCH("720",B5)),"~45 min",IF(ISNUMBER(SEARCH("750",B5)),"~45 min","~40 min")))&" per cycle"),"") -> Select package above
A22: 6. Total time | B22: =IFERROR(IF(OR(B12="",B13="",B5="Select"),"Complete inputs above",TEXT(INT(CEILING(B12/B13,1)*IF(ISNUMBER(SEARCH("1.8",B5)),70,IF(ISNUMBER(SEARCH("720",B5)),45,IF(ISNUMBER(SEARCH("750",B5)),45,40)))/60),"0")&"h "&TEXT(MOD(CEILING(B12/B13,1)*IF(ISNUMBER(SEARCH("1.8",B5)),70,IF(ISNUMBER(SEARCH("720",B5)),45,IF(ISNUMBER(SEARCH("750",B5)),45,40))),60),"0")&"m"&IF(ISNUMBER(SEARCH("Full",B4))," (×2 for 2x hi-ire)","")),"") -> Complete inputs above
A24: STORAGE GUIDANCE
A25: 7. Store at | B25: =IFERROR(IF(OR(B8="Select",B10="Select"),"Complete inputs above",IF(ISNUMBER(SEARCH("Unpasteurized",B8)),"5°C refrigerated REQUIRED",IF(AND(ISNUMBER(SEARCH("Twice",B8)),B7>=15,OR(ISNUMBER(SEARCH("Age",B10)),ISNUMBER(SEARCH("Long",B10)))),IF(B11="Select","Ambient or warm OK for aging",B11),IF(AND(ISNUMBER(SEARCH("Twice",B8)),B7>=15),"Cool or ambient OK",IF(B7>=15,"Cool (10-15°C) recommended","Refrigerated (5°C) recommended"))))),"") -> Complete inputs above
A26: 8. Duration | B26: =IFERROR(IF(OR(B8="Select",B10="Select"),"Complete inputs above",IF(ISNUMBER(SEARCH("Unpasteurized",B8)),"Weeks only - ship fast!",IF(ISNUMBER(SEARCH("Long",B10)),IF(AND(ISNUMBER(SEARCH("Twice",B8)),B7>=17),"Years OK (even warm)","Years OK (keep cool)"),IF(ISNUMBER(SEARCH("Age",B10)),IF(ISNUMBER(SEARCH("Twice",B8)),"1-3 years OK","6-12 months max"),IF(ISNUMBER(SEARCH("6+",B10)),"6-12 months OK",IF(ISNUMBER(SEARCH("1-3",B10)),"3 months OK","Ship when ready")))))),"") -> Complete inputs above
A27: 9. Stability | B27: =IFERROR(IF(OR(B4="Select",B8="Select"),"Complete inputs above",IF(ISNUMBER(SEARCH("Unpasteurized",B8)),"LOW - cold chain required",IF(AND(ISNUMBER(SEARCH("Twice",B8)),B7>=15),"HIGH - room temp storage OK",IF(AND(ISNUMBER(SEARCH("Full",B4)),B7>=15),"HIGH - room temp storage OK",IF(B7>=15,"MODERATE - cool storage","LOW - refrigerate"))))),"") -> Complete inputs above
A29: KILL STATUS
A30: Yeast | B30: =IF(B4="Select","—","Dead") -> —
A31: Enzymes | B31: =IF(B4="Select","—",IF(ISNUMBER(SEARCH("yeast only",B4)),"ACTIVE - flavor evolving","Dead")) -> —
A32: Hiochi bacteria | B32: =IF(B4="Select","—",IF(OR(ISNUMBER(SEARCH("Full",B4)),ISNUMBER(SEARCH("Export",B4))),"Dead",IF(AND(B7>=15,ISNUMBER(SEARCH("enzymes",B4))),"Likely dead (high ABV)","RISK - may survive"))) -> —
A34: WARNINGS
A35: =IF(AND(B7<12,B7<>""),"⚠ LOW ABV (<12%): Consider 2x pasteurization + cold chain","")
A36: =IF(ISNUMBER(SEARCH("Air",B9)),"⚠ AIR COOLING: Slow! Adds PU, risks flavor damage","")
A37: =IF(OR(ISNUMBER(SEARCH("Plate",B6)),ISNUMBER(SEARCH("Jakan",B6)),ISNUMBER(SEARCH("Jacketed",B6))),"ℹ BULK METHOD: Sterile fill required after pasteurization","")
A38: =IF(AND(ISNUMBER(SEARCH("Warm",B11)),NOT(ISNUMBER(SEARCH("Twice",B8)))),"⚠ WARM STORAGE: Requires twice-pasteurized sake","")
A39: =IF(AND(ISNUMBER(SEARCH("Full",B4)),NOT(ISNUMBER(SEARCH("Twice",B8)))),"ℹ Full stability requires TWICE pasteurized (change strategy above)","")
A40: =IF(AND(A35="",A36="",A37="",A38="",A39=""),"✓ No warnings - settings look good!","") -> ✓ No warnings - settings look good!
A41: REFERENCE
A43: PU FORMULA
A44: PU = t × 10^((T-60)/Z)
A45: Z = 6.94°C (thermal resistance)
A47: PU EQUIVALENTS
...

Sheet Troubleshooting
A1: TROUBLESHOOTING
A2: Common problems, causes, and solutions for koji-based fermentation
A4: Problem | B4: Likely Cause | C4: Solution
A5: KOJI PROBLEMS
A7: No visible growth after 24 hrs | B7: Temperature too low (<28°C), dead spores, sterilized environment, rice too dry | C7: Ensure 30-32°C, use fresh tane-koji, don't over-sanitize muro, check rice moisture 38%
A8: Nuri-haze (surface only, no penetration) | B8: Rice surface too wet, hard center from undersoaking. Fungi get moisture from surface, no drive to penetrate. | C8: Proper soaking (28-30% absorption), cool rice to reduce surface moisture before inoculation, target 38% total moisture
A9: Baka-haze (deep growth, low enzyme) | B9: Excessive moisture triggers glucose effect. High glucose suppresses enzyme genes via feedback inhibition. | C9: Reduce moisture, don't over-soak, ensure proper steaming. Rice should not squash easily.
A10: Haze-ochi (sparse/no growth) | B10: Too cool, too dry, contamination, poor spore quality, bad hygiene | C10: Check temps 30-35°C, humidity 80%+, use fresh spores, clean equipment
A11: Green/black spores appearing | B11: Koji sporulating - went too long or too hot. Indicates over-maturity. | C11: Harvest earlier (before 48hrs for most methods), keep peak temp under 42°C
A12: Ammonia smell | B12: Excessive protein breakdown from high protease activity, often from over-fermentation or contamination | C12: Shorter incubation, lower temps, ensure clean environment
A13: Sour/vinegar smell in koji | B13: Bacterial contamination (Acetobacter or LAB) | C13: Improve sanitation, check water source, ensure proper temp (bacteria slower at higher koji temps)
A15: MOTO (YEAST STARTER) PROBLEMS
A17: No fermentation activity | B17: Dead yeast, too cold (<10°C), too much lactic acid, nutrient deficiency (phosphate) | C17: Fresh yeast, warm to 15-20°C, check lactic acid dose (650-700mL/100L), add yeast nutrient
A18: Stuck fermentation | B18: Temperature shock, nutrient deficiency (esp. phosphate <250mg/L), excessive alcohol | C18: Maintain stable temps, add phosphate/nutrients, ensure moto doesn't exceed 15% ABV
A19: Over-acidification (kimoto/yamahai) | B19: LAB dominated too long, temperature stayed in LAB-optimal range (20-30°C) | C19: Move to warmer temps (35°C+) to kill LAB and favor yeast, or restart
A20: Contamination (film/off-odor) | B20: Wild yeast, bacteria from equipment or air, insufficient acidity | C20: Better sanitation, ensure pH drops to 4.0 or below, consider sokujo method
A21: Slow start (kimoto/yamahai) | B21: Normal - traditional methods take 3-4 weeks. Not a problem unless off-odors develop. | C21: Patience. Monitor for contamination but don't rush. Natural LAB takes time.
A23: MOROMI (MAIN FERMENTATION) PROBLEMS
A25: Fermentation too fast/hot | B25: Temperature too high, too much koji, hard water accelerating yeast | C25: Cool to 10-15°C (ginjo) or 15-18°C (junmai). Reduce koji ratio. Consider softer water.
A26: Fermentation too slow | B26: Too cold, weak yeast, soft water, insufficient nutrients | C26: Warm slightly, ensure healthy moto, add minerals to moto water, check koji quality
A27: Stuck at low alcohol (12-14%) | B27: Weak yeast, nutrient deficiency, osmotic stress from high sugar | C27: Use alcohol-tolerant yeast (Kyokai #7, #9), ensure adequate nutrients, proper sandan-jikomi staging
A28: Foaming overflow | B28: Vigorous fermentation, foam-positive yeast strain | C28: Use foam-negative yeast, larger vessel, add rice bran (nuka) to break foam, lower temperature
A29: Off-flavors developing | B29: Contamination, autolysis (yeast death), oxidation, high ferment temp | C29: Check sanitation, don't over-extend ferment, minimize oxygen exposure, control temperature
A30: Film on surface (hiochi) | B30: Hiochi bacteria - sake-spoiling LAB that survives alcohol | C30: Pasteurize immediately, improve sanitation for next batch, lower pH
A32: WATER PROBLEMS
A34: Red/brown discoloration | B34: Iron >0.02 ppm binding with koji compounds to form colored complexes | C34: Filter water with activated carbon, use iron-free source, aerate then filter
A35: Light-struck off-flavors | B35: Manganese >0.02 ppm catalyzing photo-oxidation under UV/light exposure | C35: Remove Mn from water, store sake in dark, use brown/UV-blocking bottles
A36: Harsh/mineral taste | B36: Excessive hardness, high sulfate, high chloride | C36: Dilute with soft water, use RO/distilled for warimizu, match water to style
A37: Thin/weak fermentation | B37: Water too soft, lacking K/Mg/P for yeast health | C37: Add minerals to moto water: KCl, MgSO4, yeast nutrient. See Water Calc sheet.
A39: FINISHED SAKE PROBLEMS
A41: Too sweet (high nihonshudo negative) | B41: Incomplete fermentation, too much residual sugar, weak koji enzymes | C41: Extend fermentation, use stronger koji, higher ferment temp, more active yeast
A42: Too dry/harsh | B42: Over-fermentation, high amino acidity, excessive alcohol | C42: Shorten ferment, use less protease-active koji, blend with sweeter sake
A43: High amino acidity (heavy/rough) | B43: Excessive protein breakdown, low polish ratio with high yeast, wrong koji type | C43: Higher polish, tsuki-haze koji, cooler ferment to reduce amino production
A44: Lacks aroma (no ginjo-ka) | B44: Ferment too warm (drives off esters), wrong yeast, sou-haze koji | C44: Lower ferment to 10-12°C, use aromatic yeast (#9, #1801), tsuki-haze koji, high polish
A45: Sulfur/rotten egg smell | B45: Yeast stress producing H2S, or contamination | C45: Better yeast nutrition, avoid temperature swings, aerate briefly (racking)
A46: Oxidized/sherry-like | B46: Oxygen exposure during storage, incomplete pasteurization | C46: Minimize headspace, proper pasteurization, store cold and dark
A47: Hazy/cloudy (unwanted) | B47: Protein/starch haze, incomplete pressing, bacterial contamination | C47: Fine filtration, bentonite fining, pasteurize to precipitate proteins
A49: OTHER KOJI FERMENTS
A51: Miso too salty | B51: Salt ratio too high, insufficient fermentation time | C51: Use 10-12% salt (not 13%+), extend aging 6+ months for salt to mellow
A52: Miso darkening too fast | B52: High temperature storage, high moisture, air exposure (Maillard reaction) | C52: Store cool, ensure proper tamari layer forms, minimize air contact
...

Sheet _Allocations
A1: Totals
A2: Rice kg | B2: =IF(OR(_Inputs!B4="",_Inputs!B4=0),"",_Inputs!B4) -> 99
A3: Koji kg | B3: =IF(OR(B2="",B2=0,_Inputs!B5=""),"",B2*_Inputs!B5) -> 21.78
A4: Water L | B4: =IF(OR(B2="",B2=0),"",B2*IFERROR(VLOOKUP(_Inputs!B1,_Presets!$A$2:$C$100,3,FALSE()),1.3)) -> 128.7
A5: Mash mass (kg actual) | B5: =IF(OR(B2="",B2=0),"",(B2-B3)*1.3 + B3*(1+_Constants!B16) + B4) -> 254.3508
A6: Theoretical volume L | B6: =IF(OR(B5="",B5=0),"",B5/_Constants!B2) -> 267.73768
A7: Genshu yield (L) | B7: =IF(OR(_Allocations!B2="",B2=0),"",_Allocations!B2*_Constants!B17*IF(OR(_Inputs!B33="",_Inputs!B33=0),0.68,_Inputs!B33)) -> 121.176
A8: Diluted yield (L) @15% | B8: =IF(OR(_Allocations!B7="",_Allocations!B7=0),"",_Allocations!B7*(_Constants!B18/15)) -> 147.02688
A9: Moromi (excl moto) | B9: =IF(OR($B$2="",B2=0,_Inputs!$B$7=""),"",$B$2*(1-_Inputs!$B$7)) -> 92.07 | C9: =IF(OR(_Allocations!$B$3="",_Allocations!$B$3=0),"",_Allocations!$B$3-_Allocations!C11) -> 19.4931 | D9: =IF(OR($B$4="",$B$4=0),"",_Allocations!$B$4-_Allocations!D11) -> 121.077
A10: Stage | B10: Rice kg | C10: Koji kg | D10: Water L
A11: Moto | B11: =IF(OR($B$2="",B2=0,_Inputs!$B$7=""),"",$B$2*_Inputs!$B$7) -> 6.93 | C11: =IF(OR(_Allocations!B11="",_Allocations!B11=0),"",_Allocations!B11*_Inputs!$B$17) -> 2.2869 | D11: =IF(OR($B$2="",B2=0),"",$B$2*_Inputs!$B$7*_Inputs!$B$18) -> 7.623
A12: Soe | B12: =IF(OR($B$9="",B9=0,_Inputs!B8=""),"",$B$9*_Inputs!B8) -> 13.8105 | C12: =IF(OR(_Allocations!$C$9="",_Allocations!C9=0),"",_Allocations!$C$9*_Inputs!$B$12) -> 5.458068 | D12: =IF(OR($B$9="",B9=0),"",$B$9*_Inputs!$B$8*_Inputs!$B$20) -> 13.119975
A13: Naka | B13: =IF(OR($B$9="",B9=0,_Inputs!B9=""),"",$B$9*_Inputs!B9) -> 32.2245 | C13: =IF(OR(_Allocations!$C$9="",_Allocations!C9=0),"",_Allocations!$C$9*_Inputs!$B$13) -> 4.288482 | D13: =IF(OR($B$9="",B9=0),"",$B$9*_Inputs!$B$9*_Inputs!$B$21) -> 40.280625
A14: Tome | B14: =IF(OR($B$9="",B9=0,_Inputs!B10=""),"",$B$9*_Inputs!B10) -> 46.035 | C14: =IF(OR(_Allocations!$C$9="",_Allocations!C9=0),"",_Allocations!$C$9*_Inputs!$B$14) -> 3.508758 | D14: =IF(OR($B$9="",B9=0),"",$B$9*_Inputs!$B$10*_Inputs!$B$16) -> 66.75075
A15: Yon | B15: =IF(OR($B$9="",B9=0,_Inputs!B11=""),"",$B$9*_Inputs!B11) -> 0 | C15: =IF(OR(_Allocations!$C$9="",_Allocations!C9=0),"",_Allocations!$C$9*_Inputs!$B$15) -> 0 | D15: =IF(OR($B$9="",B9=0),"",$B$9*_Inputs!$B$11*_Inputs!$B$22) -> 0
A17: Koji sizing (Ueda)
A18: Dry koji required (kg dry) | B18: =IF(OR(B3="",B3=0),"",B3) -> 21.78
A19: Steamed weight (kg post‑steam) | B19: =IF(OR(B3="",B3=0),"",B3/(1-_Constants!B6)) -> 37.551724
A20: Pre‑inoc weight (kg pre‑inoc) | B20: =IF(OR(B3="",B3=0),"",B3/(1-_Constants!B7)) -> 31.114286
A21: Estimated trays | B21: =IF(OR(B19="",B19=0),"",CEILING(B19/_Constants!B8,1)) -> 26
A22: Moto rice breakdown
A23: Moto raw rice (kg) | B23: =IF(OR(B11="",B11=0,_Inputs!B19=""),"",B11*_Inputs!B19) -> 0
A24: Moto kakemai (kg dry) | B24: =IF(OR(_Allocations!B11="",_Allocations!B11=0),"",(B11-IFERROR(B23,0)-IFERROR(_Allocations!C11,0))) -> 4.6431
A26: NITROGEN PROFILE
A27: Crude protein (%) | B27: =_Inputs!B26
A28: Digestible fraction (G/TP) | B28: =_Inputs!B27 -> 0.41
A29: Locked fraction (P/TP) | B29: =_Inputs!B28 -> 0.21
A30: G/P ratio | B30: =_Inputs!B29 -> 1.97
A32: AMINO TENDENCY
A33: Seimaibuai factor | B33: =IF(OR(_Inputs!B24="",_Inputs!B24=0),"",IF(_Inputs!B24>=90,0.6,IF(_Inputs!B24>=80,0.8,IF(_Inputs!B24>=70,1,IF(_Inputs!B24>=60,0.9,IF(_Inputs!B24>=50,0.75,0.6))))))
A34: Amino tendency score | B34: =IF(OR(B27="",B28="",B33=""),"",ROUND(B27*B28*B33,1))
A35: Amino tendency | B35: =IF(B34="","",IF(B34<1.5,"Very Low",IF(B34<2,"Low",IF(B34<2.5,"Medium",IF(B34<3,"High","Very High")))))
A37: FERMENTATION VIGOR
A38: Vigor factor | B38: =IF(OR(_Inputs!B24="",_Inputs!B24=0),"",IF(_Inputs!B24>=90,1.5,IF(_Inputs!B24>=80,1.25,IF(_Inputs!B24>=70,1,IF(_Inputs!B24>=60,0.85,0.7)))))
A39: Vigor level | B39: =IF(B38="","",IF(B38>=1.4,"Very Fast",IF(B38>=1.15,"Fast",IF(B38>=0.9,"Standard",IF(B38>=0.75,"Slow","Very Slow")))))
A40: Vigor warning | B40: =IF(B38="","",IF(B38>=1.4,"⚠ Monitor closely - expect rapid ferment",IF(B38<=0.75,"⚠ Extended timeline - watch for stuck ferment","")))
A43: CHART DATA
A44: Stage | B44: Raw Rice | C44: Kakemai | D44: Koji | E44: Water
A45: Moto | B45: =IFERROR(_Allocations!B23,0) -> 0 | C45: =IFERROR(_Allocations!B24,0) -> 4.6431 | D45: =IFERROR(_Allocations!C11,0) -> 2.2869 | E45: =IFERROR(_Allocations!D11,0) -> 7.623
A46: Soe | B46: =0 -> 0 | C46: =IFERROR(_Allocations!B12,0) -> 13.8105 | D46: =IFERROR(_Allocations!C12,0) -> 5.458068 | E46: =IFERROR(_Allocations!D12,0) -> 13.119975
...

Sheet _Inputs
A1: Preset name | B1: =Recipe!B5 -> Select ▽
A2: Baseline index | B2: =IFERROR(MATCH(_Inputs!B1,_Presets!$A$2:$A$100,0),"") -> 1
A4: Total rice (kg) | B4: =Recipe!B4 -> 99
A5: Koji fraction | B5: =IF(_Inputs!B2="",0.2,INDEX(_Presets!$B$2:$B$100,_Inputs!B2)) -> 0.22
A6: Water L/kg | B6: =IF(B1="Select","",IFERROR(VLOOKUP(B1,_Presets!$A$2:$C$100,3,FALSE()),1.3)) -> 1.3
A7: Moto % of total | B7: =IF(_Inputs!B2="",0.07,INDEX(_Presets!$P$2:$P$100,_Inputs!B2)) -> 0.07
A8: Soe % | B8: =IF(_Inputs!B2="",0.27,INDEX(_Presets!$D$2:$D$100,_Inputs!B2)) -> 0.15
A9: Naka % | B9: =IF(_Inputs!B2="",0.34,INDEX(_Presets!$E$2:$E$100,_Inputs!B2)) -> 0.35
A10: Tome % | B10: =IF(_Inputs!B2="",0.39,INDEX(_Presets!$F$2:$F$100,_Inputs!B2)) -> 0.5
A11: Yon % | B11: =IF(_Inputs!B2="",0,INDEX(_Presets!$G$2:$G$100,_Inputs!B2)) -> 0
A12: Koji Soe % | B12: =IF(_Inputs!B2="","",INDEX(_Presets!$H$2:$H$100,_Inputs!B2)) -> 0.28
A13: Koji Naka % | B13: =IF(_Inputs!B2="","",INDEX(_Presets!$I$2:$I$100,_Inputs!B2)) -> 0.22
A14: Koji Tome % | B14: =IF(_Inputs!B2="","",INDEX(_Presets!$J$2:$J$100,_Inputs!B2)) -> 0.18
A15: Koji Yon % | B15: =IF(_Inputs!B2="","",INDEX(_Presets!$K$2:$K$100,_Inputs!B2)) -> 0
A16: Water Tome | B16: =IF(_Inputs!B2="","",INDEX(_Presets!$N$2:$N$100,_Inputs!B2)) -> 1.45
A17: Moto Koji % | B17: =IF(_Inputs!B2="","",INDEX(_Presets!$Q$2:$Q$100,_Inputs!B2)) -> 0.33
A18: Moto Water % | B18: =IF(_Inputs!B2="","",INDEX(_Presets!$R$2:$R$100,_Inputs!B2)) -> 1.1
A19: Moto Raw Rice % | B19: =IF(_Inputs!B2="","",INDEX(_Presets!$S$2:$S$100,_Inputs!B2)) -> 0
A20: Water Soe % | B20: =IF(_Inputs!B2="","",INDEX(_Presets!$L$2:$L$100,_Inputs!B2)) -> 0.95
A21: Water Naka % | B21: =IF(_Inputs!B2="","",INDEX(_Presets!$M$2:$M$100,_Inputs!B2)) -> 1.25
A22: Water Yon % | B22: =IF(_Inputs!B2="","",INDEX(_Presets!$O$2:$O$100,_Inputs!B2)) -> 0
A24: Seimaibuai | B24: =IF(Recipe!B18="Select","",IF(Recipe!B18="Lot A",IF(Recipe!C11="",IF(_Inputs!$B$2<>"",INDEX(_Presets!$U$2:$U$100,_Inputs!$B$2),70),Recipe!C11),IF(Recipe!B18="Lot B",IF(Recipe!C12="",IF(_Inputs!$B$2<>"",INDEX(_Presets!$U$2:$U$100,_Inputs!$B$2),70),Recipe!C12),IF(Recipe!B18="Lot C",IF(Recipe!C13="",IF(_Inputs!$B$2<>"",INDEX(_Presets!$U$2:$U$100,_Inputs!$B$2),70),Recipe!C13),IF(Recipe!B18="Lot D",IF(Recipe!C14="",IF(_Inputs!$B$2<>"",INDEX(_Presets!$U$2:$U$100,_Inputs!$B$2),70),Recipe!C14),""))))) -> 0
A25: Rice variety | B25: =IF(Recipe!B18="Select","",IF(Recipe!B18="Lot A",Recipe!B11,IF(Recipe!B18="Lot B",Recipe!B12,IF(Recipe!B18="Lot C",Recipe!B13,IF(Recipe!B18="Lot D",Recipe!B14,""))))) -> Select ▽
A26: Crude protein % | B26: =IF(OR(_Inputs!B24="",_Inputs!B24=0),"",IF(_Inputs!B24>=90,7.5,IF(_Inputs!B24>=80,6.4,IF(_Inputs!B24>=70,5.25,IF(_Inputs!B24>=60,4,IF(_Inputs!B24>=50,2.9,IF(_Inputs!B24>=40,2.2,1.8)))))))
A27: G/TP ratio | B27: =IFERROR(VLOOKUP(B25,_Lookups!$P$2:$U$20,2,FALSE()),0.41) -> 0.41
A28: P/TP ratio | B28: =IFERROR(VLOOKUP(B25,_Lookups!$P$2:$U$20,3,FALSE()),0.21) -> 0.21
A29: G/P ratio | B29: =IFERROR(VLOOKUP(B25,_Lookups!$P$2:$U$20,4,FALSE()),1.97) -> 1.97
A30: Koji mold type | B30: =IFERROR(VLOOKUP(Recipe!B7,_Lookups!$B$2:$C$40,2,FALSE()),"")
A31: Citric factor | B31: =IFERROR(VLOOKUP(B30,_Lookups!$V$2:$W$5,2,FALSE()),0) -> 0
A32: Press method | B32: =Recipe!B36 -> Select ▽
A33: Press efficiency | B33: =IFERROR(VLOOKUP(_Inputs!B32,_Lookups!$CH$1:$CI$20,2,FALSE()),"") -> 0

Sheet _Presets
A1: Name | B1: KojiPct | C1: WaterLkg | D1: RiceSoe | E1: RiceNaka | F1: RiceTome | G1: RiceYon | H1: KojiSoe | I1: KojiNaka | J1: KojiTome | K1: KojiYon | L1: WaterSoe | M1: WaterNaka | N1: WaterTome | O1: WaterYon | P1: MotoPct | Q1: MotoKojiPct | R1: MotoWaterPct | S1: MotoRawRicePct | T1: LotA_Variety | U1: LotA_Polish | V1: LotB_Variety | W1: LotB_Polish | X1: Koji_Lot | Y1: MotoRaw_Lot | Z1: MotoStm_Lot | AA1: Soe_Lot | AB1: Naka_Lot | AC1: Tome_Lot | AD1: Yon_Lot
A2: Select ▽ | B2: 0.22 | C2: 1.3 | D2: 0.15 | E2: 0.35 | F2: 0.5 | G2: 0 | H2: 0.28 | I2: 0.22 | J2: 0.18 | K2: 0 | L2: 0.95 | M2: 1.25 | N2: 1.45 | O2: 0 | P2: 0.07 | Q2: 0.33 | R2: 1.1 | S2: 0
A3: Custom | B3: 0.23 | C3: 1.3 | D3: 0.2 | E3: 0.3 | F3: 0.5 | G3: 0 | H3: 0.6 | I3: 0.3 | J3: 0.1 | K3: 0 | L3: 0.4 | M3: 0.3 | N3: 0.3 | O3: 0 | P3: 0.07 | Q3: 0.33 | R3: 1.2 | S3: 0
A4: Standard_NRIB | B4: 0.217 | C4: 1.3 | D4: 0.1667 | E4: 0.3333 | F4: 0.5 | G4: 0 | H4: 0.222 | I4: 0.333 | J4: 0.444 | K4: 0 | L4: 0.95 | M4: 1.25 | N4: 1.45 | O4: 0 | P4: 0.07 | Q4: 0.308 | R4: 1.1 | S4: 0 | T4: Generic | U4: 70 | X4: Lot A | Y4: Lot A | Z4: Lot A | AA4: Lot A | AB4: Lot A | AC4: Lot A | AD4: Lot A
A5: Junmai | B5: 0.22 | C5: 1.3 | D5: 0.1667 | E5: 0.3333 | F5: 0.5 | G5: 0 | H5: 0.222 | I5: 0.333 | J5: 0.444 | K5: 0 | L5: 0.95 | M5: 1.25 | N5: 1.45 | O5: 0 | P5: 0.07 | Q5: 0.33 | R5: 1.1 | S5: 0 | T5: Gohyakumangoku | U5: 70 | X5: Lot A | Y5: Lot A | Z5: Lot A | AA5: Lot A | AB5: Lot A | AC5: Lot A | AD5: Lot A
A6: Ginjo | B6: 0.22 | C6: 1.3 | D6: 0.1667 | E6: 0.3333 | F6: 0.5 | G6: 0 | H6: 0.222 | I6: 0.333 | J6: 0.444 | K6: 0 | L6: 0.95 | M6: 1.25 | N6: 1.45 | O6: 0 | P6: 0.07 | Q6: 0.33 | R6: 1.1 | S6: 0 | T6: Yamadanishiki | U6: 55 | X6: Lot A | Y6: Lot A | Z6: Lot A | AA6: Lot A | AB6: Lot A | AC6: Lot A | AD6: Lot A
A7: Junmai_Ginjo | B7: 0.22 | C7: 1.3 | D7: 0.1667 | E7: 0.3333 | F7: 0.5 | G7: 0 | H7: 0.222 | I7: 0.333 | J7: 0.444 | K7: 0 | L7: 0.95 | M7: 1.25 | N7: 1.45 | O7: 0 | P7: 0.07 | Q7: 0.33 | R7: 1.1 | S7: 0 | T7: Yamadanishiki | U7: 55 | X7: Lot A | Y7: Lot A | Z7: Lot A | AA7: Lot A | AB7: Lot A | AC7: Lot A | AD7: Lot A
A8: Daiginjo | B8: 0.22 | C8: 1.3 | D8: 0.1667 | E8: 0.3333 | F8: 0.5 | G8: 0 | H8: 0.222 | I8: 0.333 | J8: 0.444 | K8: 0 | L8: 0.95 | M8: 1.25 | N8: 1.45 | O8: 0 | P8: 0.07 | Q8: 0.33 | R8: 1.1 | S8: 0 | T8: Yamadanishiki | U8: 35 | X8: Lot A | Y8: Lot A | Z8: Lot A | AA8: Lot A | AB8: Lot A | AC8: Lot A | AD8: Lot A
A9: Junmai_Daiginjo | B9: 0.22 | C9: 1.3 | D9: 0.1667 | E9: 0.3333 | F9: 0.5 | G9: 0 | H9: 0.222 | I9: 0.333 | J9: 0.444 | K9: 0 | L9: 0.95 | M9: 1.25 | N9: 1.45 | O9: 0 | P9: 0.07 | Q9: 0.33 | R9: 1.1 | S9: 0 | T9: Yamadanishiki | U9: 40 | X9: Lot A | Y9: Lot A | Z9: Lot A | AA9: Lot A | AB9: Lot A | AC9: Lot A | AD9: Lot A
A10: Honjozo | B10: 0.22 | C10: 1.3 | D10: 0.1667 | E10: 0.3333 | F10: 0.5 | G10: 0 | H10: 0.222 | I10: 0.333 | J10: 0.444 | K10: 0 | L10: 0.95 | M10: 1.25 | N10: 1.45 | O10: 0 | P10: 0.07 | Q10: 0.33 | R10: 1.1 | S10: 0 | T10: Gohyakumangoku | U10: 70 | X10: Lot A | Y10: Lot A | Z10: Lot A | AA10: Lot A | AB10: Lot A | AC10: Lot A | AD10: Lot A
A11: Gauntner_Standard | B11: 0.229 | C11: 1.22 | D11: 0.1497 | E11: 0.2941 | F11: 0.4706 | G11: 0 | H11: 0.222 | I11: 0.333 | J11: 0.444 | K11: 0 | L11: 0.9286 | M11: 1.2 | N11: 1.4318 | O11: 0 | P11: 0.065 | Q11: 0.3077 | R11: 1.0769 | S11: 0 | T11: Generic | U11: 70 | X11: Lot A | Y11: Lot A | Z11: Lot A | AA11: Lot A | AB11: Lot A | AC11: Lot A | AD11: Lot A
A12: Nihonshu_2300 | B12: 0.2335 | C12: 1.3 | D12: 0.1534 | E12: 0.2835 | F12: 0.4831 | G12: 0 | H12: 0.21 | I12: 0.26 | J12: 0.53 | K12: 0 | L12: 0.9547 | M12: 1.1764 | N12: 1.5171 | O12: 0 | P12: 0.08 | Q12: 0.3315 | R12: 1.0815 | S12: 0 | T12: Generic | U12: 70 | X12: Lot A | Y12: Lot A | Z12: Lot A | AA12: Lot A | AB12: Lot A | AC12: Lot A | AD12: Lot A
